Workbook

Sheet MTeams
A1: TeamName | B1: TeamID | C1: FirstD1Season | D1: LastD1Season
A2: Abilene Chr | B2: 1101 | C2: 2014 | D2: 2026
A3: Air Force | B3: 1102 | C3: 1985 | D3: 2026
A4: Akron | B4: 1103 | C4: 1985 | D4: 2026
A5: Alabama | B5: 1104 | C5: 1985 | D5: 2026
A6: Alabama A&M | B6: 1105 | C6: 2000 | D6: 2026
A7: Alabama St | B7: 1106 | C7: 1985 | D7: 2026
A8: SUNY Albany | B8: 1107 | C8: 2000 | D8: 2026
A9: Alcorn St | B9: 1108 | C9: 1985 | D9: 2026
A10: Alliant Intl | B10: 1109 | C10: 1985 | D10: 1991
A11: American Univ | B11: 1110 | C11: 1985 | D11: 2026
A12: Appalachian St | B12: 1111 | C12: 1985 | D12: 2026
A13: Arizona | B13: 1112 | C13: 1985 | D13: 2026
... A382: New Haven | B382: 1481 | C382: 2026 | D382: 2026

Sheet Mens Seeding
A1: Sort | B1: Seed | C1: TeamName | D1: Region | E1: TeamID | F1: AlternateTeam | G1: Duplicate
A2: 1 | B2: 1 | C2: Duke | D2: East | E2: =VLOOKUP(Table1[[#This Row],[TeamName]],MTeams!A:B,2,FALSE) -> 1181 | G2: =COUNTIF(E:E, E2) -> 1
A3: 2 | B3: 16 | C3: Tennessee St | D3: East | E3: =VLOOKUP(Table1[[#This Row],[TeamName]],MTeams!A:B,2,FALSE) -> 1398 | G3: =COUNTIF(E:E, E3) -> 1
A4: 3 | B4: 8 | C4: Utah St | D4: East | E4: =VLOOKUP(Table1[[#This Row],[TeamName]],MTeams!A:B,2,FALSE) -> 1429 | G4: =COUNTIF(E:E, E4) -> 1
A5: 4 | B5: 9 | C5: Iowa | D5: East | E5: =VLOOKUP(Table1[[#This Row],[TeamName]],MTeams!A:B,2,FALSE) -> 1234 | G5: =COUNTIF(E:E, E5) -> 1
A6: 5 | B6: 5 | C6: St John's | D6: East | E6: =VLOOKUP(Table1[[#This Row],[TeamName]],MTeams!A:B,2,FALSE) -> 1385 | G6: =COUNTIF(E:E, E6) -> 1
A7: 6 | B7: 12 | C7: Yale | D7: East | E7: =VLOOKUP(Table1[[#This Row],[TeamName]],MTeams!A:B,2,FALSE) -> 1463 | G7: =COUNTIF(E:E, E7) -> 1
A8: 7 | B8: 4 | C8: Alabama | D8: East | E8: =VLOOKUP(Table1[[#This Row],[TeamName]],MTeams!A:B,2,FALSE) -> 1104 | G8: =COUNTIF(E:E, E8) -> 1
A9: 8 | B9: 13 | C9: SF Austin | D9: East | E9: =VLOOKUP(Table1[[#This Row],[TeamName]],MTeams!A:B,2,FALSE) -> 1372 | G9: =COUNTIF(E:E, E9) -> 1
A10: 9 | B10: 6 | C10: Wisconsin | D10: East | E10: =VLOOKUP(Table1[[#This Row],[TeamName]],MTeams!A:B,2,FALSE) -> 1458 | G10: =COUNTIF(E:E, E10) -> 1
A11: 10 | B11: 11 | C11: Santa Clara | D11: East | E11: =VLOOKUP(Table1[[#This Row],[TeamName]],MTeams!A:B,2,FALSE) -> 1365 | F11: SMU | G11: =COUNTIF(E:E, E11) -> 1
A12: 11 | B12: 3 | C12: Iowa St | D12: East | E12: =VLOOKUP(Table1[[#This Row],[TeamName]],MTeams!A:B,2,FALSE) -> 1235 | G12: =COUNTIF(E:E, E12) -> 1
A13: 12 | B13: 14 | C13: Troy | D13: East | E13: =VLOOKUP(Table1[[#This Row],[TeamName]],MTeams!A:B,2,FALSE) -> 1407 | G13: =COUNTIF(E:E, E13) -> 1
A14: 13 | B14: 7 | C14: Villanova | D14: East | E14: =VLOOKUP(Table1[[#This Row],[TeamName]],MTeams!A:B,2,FALSE) -> 1437 | G14: =COUNTIF(E:E, E14) -> 1
A15: 14 | B15: 10 | C15: Missouri | D15: East | E15: =VLOOKUP(Table1[[#This Row],[TeamName]],MTeams!A:B,2,FALSE) -> 1281 | G15: =COUNTIF(E:E, E15) -> 1
A16: 15 | B16: 2 | C16: Michigan St | D16: East | E16: =VLOOKUP(Table1[[#This Row],[TeamName]],MTeams!A:B,2,FALSE) -> 1277 | G16: =COUNTIF(E:E, E16) -> 1
A17: 16 | B17: 15 | C17: Wright St | D17: East | E17: =VLOOKUP(Table1[[#This Row],[TeamName]],MTeams!A:B,2,FALSE) -> 1460 | G17: =COUNTIF(E:E, E17) -> 1
A18: 1 | B18: 1 | C18: Michigan | D18: Midwest | E18: =VLOOKUP(Table1[[#This Row],[TeamName]],MTeams!A:B,2,FALSE) -> 1276 | G18: =COUNTIF(E:E, E18) -> 1
A19: 2 | B19: 16 | C19: UMBC | D19: Midwest | E19: =VLOOKUP(Table1[[#This Row],[TeamName]],MTeams!A:B,2,FALSE) -> 1420 | F19: LIU Brooklyn | G19: =COUNTIF(E:E, E19) -> 1
A20: 3 | B20: 8 | C20: St Louis | D20: Midwest | E20: =VLOOKUP(Table1[[#This Row],[TeamName]],MTeams!A:B,2,FALSE) -> 1387 | G20: =COUNTIF(E:E, E20) -> 1
A21: 4 | B21: 9 | C21: TCU | D21: Midwest | E21: =VLOOKUP(Table1[[#This Row],[TeamName]],MTeams!A:B,2,FALSE) -> 1395 | G21: =COUNTIF(E:E, E21) -> 1
A22: 5 | B22: 5 | C22: Tennessee | D22: Midwest | E22: =VLOOKUP(Table1[[#This Row],[TeamName]],MTeams!A:B,2,FALSE) -> 1397 | G22: =COUNTIF(E:E, E22) -> 1
A23: 6 | B23: 12 | C23: Liberty | D23: Midwest | E23: =VLOOKUP(Table1[[#This Row],[TeamName]],MTeams!A:B,2,FALSE) -> 1251 | G23: =COUNTIF(E:E, E23) -> 1
A24: 7 | B24: 4 | C24: Virginia | D24: Midwest | E24: =VLOOKUP(Table1[[#This Row],[TeamName]],MTeams!A:B,2,FALSE) -> 1438 | G24: =COUNTIF(E:E, E24) -> 1
A25: 8 | B25: 13 | C25: N Dakota St | D25: Midwest | E25: =VLOOKUP(Table1[[#This Row],[TeamName]],MTeams!A:B,2,FALSE) -> 1295 | G25: =COUNTIF(E:E, E25) -> 1
A26: 9 | B26: 6 | C26: North Carolina | D26: Midwest | E26: =VLOOKUP(Table1[[#This Row],[TeamName]],MTeams!A:B,2,FALSE) -> 1314 | G26: =COUNTIF(E:E, E26) -> 1
A27: 10 | B27: 11 | C27: VCU | D27: Midwest | E27: =VLOOKUP(Table1[[#This Row],[TeamName]],MTeams!A:B,2,FALSE) -> 1433 | F27: Auburn | G27: =COUNTIF(E:E, E27) -> 1
A28: 11 | B28: 3 | C28: Purdue | D28: Midwest | E28: =VLOOKUP(Table1[[#This Row],[TeamName]],MTeams!A:B,2,FALSE) -> 1345 | G28: =COUNTIF(E:E, E28) -> 1
A29: 12 | B29: 14 | C29: Navy | D29: Midwest | E29: =VLOOKUP(Table1[[#This Row],[TeamName]],MTeams!A:B,2,FALSE) -> 1298 | G29: =COUNTIF(E:E, E29) -> 1
A30: 13 | B30: 7 | C30: Georgia | D30: Midwest | E30: =VLOOKUP(Table1[[#This Row],[TeamName]],MTeams!A:B,2,FALSE) -> 1208 | G30: =COUNTIF(E:E, E30) -> 1
A31: 14 | B31: 10 | C31: NC State | D31: Midwest | E31: =VLOOKUP(Table1[[#This Row],[TeamName]],MTeams!A:B,2,FALSE) -> 1301 | G31: =COUNTIF(E:E, E31) -> 1
A32: 15 | B32: 2 | C32: Connecticut | D32: Midwest | E32: =VLOOKUP(Table1[[#This Row],[TeamName]],MTeams!A:B,2,FALSE) -> 1163 | G32: =COUNTIF(E:E, E32) -> 1
A33: 16 | B33: 15 | C33: Merrimack | D33: Midwest | E33: =VLOOKUP(Table1[[#This Row],[TeamName]],MTeams!A:B,2,FALSE) -> 1467 | G33: =COUNTIF(E:E, E33) -> 1
A34: 1 | B34: 1 | C34: Florida | D34: South | E34: =VLOOKUP(Table1[[#This Row],[TeamName]],MTeams!A:B,2,FALSE) -> 1196 | G34: =COUNTIF(E:E, E34) -> 1
A35: 2 | B35: 16 | C35: Howard | D35: South | E35: =VLOOKUP(Table1[[#This Row],[TeamName]],MTeams!A:B,2,FALSE) -> 1224 | F35: Bethune-Cookman | G35: =COUNTIF(E:E, E35) -> 1
A36: 3 | B36: 8 | C36: Miami FL | D36: South | E36: =VLOOKUP(Table1[[#This Row],[TeamName]],MTeams!A:B,2,FALSE) -> 1274 | G36: =COUNTIF(E:E, E36) -> 1
A37: 4 | B37: 9 | C37: Ohio St | D37: South | E37: =VLOOKUP(Table1[[#This Row],[TeamName]],MTeams!A:B,2,FALSE) -> 1326 | G37: =COUNTIF(E:E, E37) -> 1
A38: 5 | B38: 5 | C38: Arkansas | D38: South | E38: =VLOOKUP(Table1[[#This Row],[TeamName]],MTeams!A:B,2,FALSE) -> 1116 | G38: =COUNTIF(E:E, E38) -> 1
A39: 6 | B39: 12 | C39: South Florida | D39: South | E39: =VLOOKUP(Table1[[#This Row],[TeamName]],MTeams!A:B,2,FALSE) -> 1378 | G39: =COUNTIF(E:E, E39) -> 1
A40: 7 | B40: 4 | C40: Kansas | D40: South | E40: =VLOOKUP(Table1[[#This Row],[TeamName]],MTeams!A:B,2,FALSE) -> 1242 | G40: =COUNTIF(E:E, E40) -> 1
...

Sheet MNCAATourneySeeds
A1: Season | B1: Seed | C1: TeamID
A2: 2026 | B2: W01 | C2: {=_xlfn.XLOOKUP( _xlfn.SWITCH(LEFT(B2,1), "W", "East", "X", "South", "Y", "Midwest", "Z", "West") & "|" & IF(MID(B2,2,1)="0", MID(B2,3,2), MID(B2,2,3)), 'Mens Seeding'!$D$2:$D$100 & "|" & 'Mens Seeding'!$B$2:$B$100, 'Mens Seeding'!$E$2:$E$100, "Not Found" )} -> 1181
A3: 2026 | B3: W02 | C3: {=_xlfn.XLOOKUP( _xlfn.SWITCH(LEFT(B3,1), "W", "East", "X", "South", "Y", "Midwest", "Z", "West") & "|" & IF(MID(B3,2,1)="0", MID(B3,3,2), MID(B3,2,3)), 'Mens Seeding'!$D$2:$D$100 & "|" & 'Mens Seeding'!$B$2:$B$100, 'Mens Seeding'!$E$2:$E$100, "Not Found" )} -> 1277
A4: 2026 | B4: W03 | C4: {=_xlfn.XLOOKUP( _xlfn.SWITCH(LEFT(B4,1), "W", "East", "X", "South", "Y", "Midwest", "Z", "West") & "|" & IF(MID(B4,2,1)="0", MID(B4,3,2), MID(B4,2,3)), 'Mens Seeding'!$D$2:$D$100 & "|" & 'Mens Seeding'!$B$2:$B$100, 'Mens Seeding'!$E$2:$E$100, "Not Found" )} -> 1235
A5: 2026 | B5: W04 | C5: {=_xlfn.XLOOKUP( _xlfn.SWITCH(LEFT(B5,1), "W", "East", "X", "South", "Y", "Midwest", "Z", "West") & "|" & IF(MID(B5,2,1)="0", MID(B5,3,2), MID(B5,2,3)), 'Mens Seeding'!$D$2:$D$100 & "|" & 'Mens Seeding'!$B$2:$B$100, 'Mens Seeding'!$E$2:$E$100, "Not Found" )} -> 1104
A6: 2026 | B6: W05 | C6: {=_xlfn.XLOOKUP( _xlfn.SWITCH(LEFT(B6,1), "W", "East", "X", "South", "Y", "Midwest", "Z", "West") & "|" & IF(MID(B6,2,1)="0", MID(B6,3,2), MID(B6,2,3)), 'Mens Seeding'!$D$2:$D$100 & "|" & 'Mens Seeding'!$B$2:$B$100, 'Mens Seeding'!$E$2:$E$100, "Not Found" )} -> 1385
A7: 2026 | B7: W06 | C7: {=_xlfn.XLOOKUP( _xlfn.SWITCH(LEFT(B7,1), "W", "East", "X", "South", "Y", "Midwest", "Z", "West") & "|" & IF(MID(B7,2,1)="0", MID(B7,3,2), MID(B7,2,3)), 'Mens Seeding'!$D$2:$D$100 & "|" & 'Mens Seeding'!$B$2:$B$100, 'Mens Seeding'!$E$2:$E$100, "Not Found" )} -> 1458
A8: 2026 | B8: W07 | C8: {=_xlfn.XLOOKUP( _xlfn.SWITCH(LEFT(B8,1), "W", "East", "X", "South", "Y", "Midwest", "Z", "West") & "|" & IF(MID(B8,2,1)="0", MID(B8,3,2), MID(B8,2,3)), 'Mens Seeding'!$D$2:$D$100 & "|" & 'Mens Seeding'!$B$2:$B$100, 'Mens Seeding'!$E$2:$E$100, "Not Found" )} -> 1437
A9: 2026 | B9: W08 | C9: {=_xlfn.XLOOKUP( _xlfn.SWITCH(LEFT(B9,1), "W", "East", "X", "South", "Y", "Midwest", "Z", "West") & "|" & IF(MID(B9,2,1)="0", MID(B9,3,2), MID(B9,2,3)), 'Mens Seeding'!$D$2:$D$100 & "|" & 'Mens Seeding'!$B$2:$B$100, 'Mens Seeding'!$E$2:$E$100, "Not Found" )} -> 1429
A10: 2026 | B10: W09 | C10: {=_xlfn.XLOOKUP( _xlfn.SWITCH(LEFT(B10,1), "W", "East", "X", "South", "Y", "Midwest", "Z", "West") & "|" & IF(MID(B10,2,1)="0", MID(B10,3,2), MID(B10,2,3)), 'Mens Seeding'!$D$2:$D$100 & "|" & 'Mens Seeding'!$B$2:$B$100, 'Mens Seeding'!$E$2:$E$100, "Not Found" )} -> 1234
A11: 2026 | B11: W10 | C11: {=_xlfn.XLOOKUP( _xlfn.SWITCH(LEFT(B11,1), "W", "East", "X", "South", "Y", "Midwest", "Z", "West") & "|" & IF(MID(B11,2,1)="0", MID(B11,3,2), MID(B11,2,3)), 'Mens Seeding'!$D$2:$D$100 & "|" & 'Mens Seeding'!$B$2:$B$100, 'Mens Seeding'!$E$2:$E$100, "Not Found" )} -> 1281
A12: 2026 | B12: W11 | C12: {=_xlfn.XLOOKUP( _xlfn.SWITCH(LEFT(B12,1), "W", "East", "X", "South", "Y", "Midwest", "Z", "West") & "|" & IF(MID(B12,2,1)="0", MID(B12,3,2), MID(B12,2,3)), 'Mens Seeding'!$D$2:$D$100 & "|" & 'Mens Seeding'!$B$2:$B$100, 'Mens Seeding'!$E$2:$E$100, "Not Found" )} -> 1365
A13: 2026 | B13: W12 | C13: {=_xlfn.XLOOKUP( _xlfn.SWITCH(LEFT(B13,1), "W", "East", "X", "South", "Y", "Midwest", "Z", "West") & "|" & IF(MID(B13,2,1)="0", MID(B13,3,2), MID(B13,2,3)), 'Mens Seeding'!$D$2:$D$100 & "|" & 'Mens Seeding'!$B$2:$B$100, 'Mens Seeding'!$E$2:$E$100, "Not Found" )} -> 1463
... A65: 2026 | B65: Z16 | C65: {=_xlfn.XLOOKUP( _xlfn.SWITCH(LEFT(B65,1), "W", "East", "X", "South", "Y", "Midwest", "Z", "West") & "|" & IF(MID(B65,2,1)="0", MID(B65,3,2), MID(B65,2,3)), 'Mens Seeding'!$D$2:$D$100 & "|" & 'Mens Seeding'!$B$2:$B$100, 'Mens Seeding'!$E$2:$E$100, "Not Found" )} -> 1340

Sheet MNCAATourneySlots
A1: Season | B1: Slot | C1: StrongSeed | D1: WeakSeed
A2: 2026 | B2: R1W1 | C2: W01 | D2: W16
A3: 2026 | B3: R1W2 | C3: W02 | D3: W15
A4: 2026 | B4: R1W3 | C4: W03 | D4: W14
A5: 2026 | B5: R1W4 | C5: W04 | D5: W13
A6: 2026 | B6: R1W5 | C6: W05 | D6: W12
A7: 2026 | B7: R1W6 | C7: W06 | D7: W11
A8: 2026 | B8: R1W7 | C8: W07 | D8: W10
A9: 2026 | B9: R1W8 | C9: W08 | D9: W09
A10: 2026 | B10: R1X1 | C10: X01 | D10: X16
A11: 2026 | B11: R1X2 | C11: X02 | D11: X15
A12: 2026 | B12: R1X3 | C12: X03 | D12: X14
A13: 2026 | B13: R1X4 | C13: X04 | D13: X13
... A33: 2026 | B33: R1Z8 | C33: Z08 | D33: Z09

Sheet Womens Seeding
A1: Sort | B1: Seed | C1: TeamName | D1: Region | E1: TeamID | F1: AlternateTeam | G1: Duplicate
A2: 1 | B2: 1 | C2: Connecticut | D2: Region 1 | E2: =VLOOKUP(Table17[[#This Row],[TeamName]],WTeams!A:B,2,FALSE) -> 3163 | G2: =COUNTIF(E:E, E2) -> 1
A3: 2 | B3: 16 | C3: F Dickinson | D3: Region 1 | E3: =VLOOKUP(Table17[[#This Row],[TeamName]],WTeams!A:B,2,FALSE) -> 3192 | F3: Howard | G3: =COUNTIF(E:E, E3) -> 1
A4: 3 | B4: 8 | C4: NC State | D4: Region 1 | E4: =VLOOKUP(Table17[[#This Row],[TeamName]],WTeams!A:B,2,FALSE) -> 3301 | G4: =COUNTIF(E:E, E4) -> 1
A5: 4 | B5: 9 | C5: Iowa St | D5: Region 1 | E5: =VLOOKUP(Table17[[#This Row],[TeamName]],WTeams!A:B,2,FALSE) -> 3235 | G5: =COUNTIF(E:E, E5) -> 1
A6: 5 | B6: 5 | C6: Mississippi | D6: Region 1 | E6: =VLOOKUP(Table17[[#This Row],[TeamName]],WTeams!A:B,2,FALSE) -> 3279 | G6: =COUNTIF(E:E, E6) -> 1
A7: 6 | B7: 12 | C7: Virginia | D7: Region 1 | E7: =VLOOKUP(Table17[[#This Row],[TeamName]],WTeams!A:B,2,FALSE) -> 3438 | F7: Arizona St | G7: =COUNTIF(E:E, E7) -> 1
A8: 7 | B8: 4 | C8: Maryland | D8: Region 1 | E8: =VLOOKUP(Table17[[#This Row],[TeamName]],WTeams!A:B,2,FALSE) -> 3268 | G8: =COUNTIF(E:E, E8) -> 1
A9: 8 | B9: 13 | C9: Louisiana Tech | D9: Region 1 | E9: =VLOOKUP(Table17[[#This Row],[TeamName]],WTeams!A:B,2,FALSE) -> 3256 | G9: =COUNTIF(E:E, E9) -> 1
A10: 9 | B10: 6 | C10: Texas Tech | D10: Region 1 | E10: =VLOOKUP(Table17[[#This Row],[TeamName]],WTeams!A:B,2,FALSE) -> 3403 | G10: =COUNTIF(E:E, E10) -> 1
A11: 10 | B11: 11 | C11: Fairfield | D11: Region 1 | E11: =VLOOKUP(Table17[[#This Row],[TeamName]],WTeams!A:B,2,FALSE) -> 3193 | G11: =COUNTIF(E:E, E11) -> 1
A12: 11 | B12: 3 | C12: Michigan | D12: Region 1 | E12: =VLOOKUP(Table17[[#This Row],[TeamName]],WTeams!A:B,2,FALSE) -> 3276 | G12: =COUNTIF(E:E, E12) -> 1
A13: 12 | B13: 14 | C13: McNeese St | D13: Region 1 | E13: =VLOOKUP(Table17[[#This Row],[TeamName]],WTeams!A:B,2,FALSE) -> 3270 | G13: =COUNTIF(E:E, E13) -> 1
A14: 13 | B14: 7 | C14: Illinois | D14: Region 1 | E14: =VLOOKUP(Table17[[#This Row],[TeamName]],WTeams!A:B,2,FALSE) -> 3228 | G14: =COUNTIF(E:E, E14) -> 1
A15: 14 | B15: 10 | C15: Clemson | D15: Region 1 | E15: =VLOOKUP(Table17[[#This Row],[TeamName]],WTeams!A:B,2,FALSE) -> 3155 | G15: =COUNTIF(E:E, E15) -> 1
A16: 15 | B16: 2 | C16: Vanderbilt | D16: Region 1 | E16: =VLOOKUP(Table17[[#This Row],[TeamName]],WTeams!A:B,2,FALSE) -> 3435 | G16: =COUNTIF(E:E, E16) -> 1
A17: 16 | B17: 15 | C17: Loy Marymount | D17: Region 1 | E17: =VLOOKUP(Table17[[#This Row],[TeamName]],WTeams!A:B,2,FALSE) -> 3258 | G17: =COUNTIF(E:E, E17) -> 1
A18: 1 | B18: 1 | C18: UCLA | D18: Region 2 | E18: =VLOOKUP(Table17[[#This Row],[TeamName]],WTeams!A:B,2,FALSE) -> 3417 | G18: =COUNTIF(E:E, E18) -> 1
A19: 2 | B19: 16 | C19: Cal Baptist | D19: Region 2 | E19: =VLOOKUP(Table17[[#This Row],[TeamName]],WTeams!A:B,2,FALSE) -> 3465 | G19: =COUNTIF(E:E, E19) -> 1
... A34: 1 | B34: 1 | C34: Texas | D34: Region 3 | E34: =VLOOKUP(Table17[[#This Row],[TeamName]],WTeams!A:B,2,FALSE) -> 3400 | G34: =COUNTIF(E:E, E34) -> 1
A35: 2 | B35: 16 | C35: Alabama A&M | D35: Region 3 | E35: =VLOOKUP(Table17[[#This Row],[TeamName]],WTeams!A:B,2,FALSE) -> 3105 | F35: Samford | G35: =COUNTIF(E:E, E35) -> 1
A36: 3 | B36: 8 | C36: Villanova | D36: Region 3 | E36: =VLOOKUP(Table17[[#This Row],[TeamName]],WTeams!A:B,2,FALSE) -> 3437 | G36: =COUNTIF(E:E, E36) -> 1
A37: 4 | B37: 9 | C37: Virginia Tech | D37: Region 3 | E37: =VLOOKUP(Table17[[#This Row],[TeamName]],WTeams!A:B,2,FALSE) -> 3439 | G37: =COUNTIF(E:E, E37) -> 1
A38: 5 | B38: 5 | C38: Michigan St | D38: Region 3 | E38: =VLOOKUP(Table17[[#This Row],[TeamName]],WTeams!A:B,2,FALSE) -> 3277 | G38: =COUNTIF(E:E, E38) -> 1
A39: 6 | B39: 12 | C39: Murray St | D39: Region 3 | E39: =VLOOKUP(Table17[[#This Row],[TeamName]],WTeams!A:B,2,FALSE) -> 3293 | G39: =COUNTIF(E:E, E39) -> 1
A40: 7 | B40: 4 | C40: Oklahoma | D40: Region 3 | E40: =VLOOKUP(Table17[[#This Row],[TeamName]],WTeams!A:B,2,FALSE) -> 3328 | G40: =COUNTIF(E:E, E40) -> 1
A41: 8 | B41: 13 | C41: UNLV | D41: Region 3 | E41: =VLOOKUP(Table17[[#This Row],[TeamName]],WTeams!A:B,2,FALSE) -> 3424 | G41: =COUNTIF(E:E, E41) -> 1
A42: 9 | B42: 6 | C42: Notre Dame | D42: Region 3 | E42: =VLOOKUP(Table17[[#This Row],[TeamName]],WTeams!A:B,2,FALSE) -> 3323 | G42: =COUNTIF(E:E, E42) -> 1
A43: 10 | B43: 11 | C43: Rice | D43: Region 3 | E43: =VLOOKUP(Table17[[#This Row],[TeamName]],WTeams!A:B,2,FALSE) -> 3349 | G43: =COUNTIF(E:E, E43) -> 1
A44: 11 | B44: 3 | C44: Ohio St | D44: Region 3 | E44: =VLOOKUP(Table17[[#This Row],[TeamName]],WTeams!A:B,2,FALSE) -> 3326 | G44: =COUNTIF(E:E, E44) -> 1
A45: 12 | B45: 14 | C45: Vermont | D45: Region 3 | E45: =VLOOKUP(Table17[[#This Row],[TeamName]],WTeams!A:B,2,FALSE) -> 3436 | G45: =COUNTIF(E:E, E45) -> 1
A46: 13 | B46: 7 | C46: Georgia | D46: Region 3 | E46: =VLOOKUP(Table17[[#This Row],[TeamName]],WTeams!A:B,2,FALSE) -> 3208 | G46: =COUNTIF(E:E, E46) -> 1
A47: 14 | B47: 10 | C47: Princeton | D47: Region 3 | E47: =VLOOKUP(Table17[[#This Row],[TeamName]],WTeams!A:B,2,FALSE) -> 3343 | G47: =COUNTIF(E:E, E47) -> 1
... A58: 9 | B58: 6 | C58: Alabama | D58: Region 4 | E58: =VLOOKUP(Table17[[#This Row],[TeamName]],WTeams!A:B,2,FALSE) -> 3104 | G58: =COUNTIF(E:E, E58) -> 1
A59: 10 | B59: 11 | C59: Nebraska | D59: Region 4 | E59: =VLOOKUP(Table17[[#This Row],[TeamName]],WTeams!A:B,2,FALSE) -> 3304 | F59: Richmond | G59: =COUNTIF(E:E, E59) -> 1
A60: 11 | B60: 3 | C60: TCU | D60: Region 4 | E60: =VLOOKUP(Table17[[#This Row],[TeamName]],WTeams!A:B,2,FALSE) -> 3395 | G60: =COUNTIF(E:E, E60) -> 1
A61: 12 | B61: 14 | C61: Idaho | D61: Region 4 | E61: =VLOOKUP(Table17[[#This Row],[TeamName]],WTeams!A:B,2,FALSE) -> 3225 | G61: =COUNTIF(E:E, E61) -> 1
A62: 13 | B62: 7 | C62: Oregon | D62: Region 4 | E62: =VLOOKUP(Table17[[#This Row],[TeamName]],WTeams!A:B,2,FALSE) -> 3332 | G62: =COUNTIF(E:E, E62) -> 1
A63: 14 | B63: 10 | C63: S Dakota St | D63: Region 4 | E63: =VLOOKUP(Table17[[#This Row],[TeamName]],WTeams!A:B,2,FALSE) -> 3355 | G63: =COUNTIF(E:E, E63) -> 1
A64: 15 | B64: 2 | C64: Iowa | D64: Region 4 | E64: =VLOOKUP(Table17[[#This Row],[TeamName]],WTeams!A:B,2,FALSE) -> 3234 | G64: =COUNTIF(E:E, E64) -> 1
...

Sheet WTeams
A1: TeamName | B1: TeamID
A2: Abilene Chr | B2: 3101
A3: Air Force | B3: 3102
A4: Akron | B4: 3103
A5: Alabama | B5: 3104
A6: Alabama A&M | B6: 3105
A7: Alabama St | B7: 3106
A8: SUNY Albany | B8: 3107
A9: Alcorn St | B9: 3108
A10: Alliant Intl | B10: 3109
A11: American Univ | B11: 3110
A12: Appalachian St | B12: 3111
A13: Arizona | B13: 3112
... A380: New Haven | B380: 3481

Sheet WNCAATourneySeeds
A1: Season | B1: Seed | C1: TeamID
A2: 2026 | B2: W01 | C2: {=_xlfn.XLOOKUP( _xlfn.SWITCH(LEFT(B2,1), "W", "Region 1", "X", "Region 2", "Y", "Region 3", "Z", "Region 4") & "|" & IF(MID(B2,2,1)="0", MID(B2,3,2), MID(B2,2,3)), 'Womens Seeding'!$D$2:$D$100 & "|" & 'Womens Seeding'!$B$2:$B$100, 'Womens Seeding'!$E$2:$E$100, "Not Found" )} -> 3163
A3: 2026 | B3: W02 | C3: {=_xlfn.XLOOKUP( _xlfn.SWITCH(LEFT(B3,1), "W", "Region 1", "X", "Region 2", "Y", "Region 3", "Z", "Region 4") & "|" & IF(MID(B3,2,1)="0", MID(B3,3,2), MID(B3,2,3)), 'Womens Seeding'!$D$2:$D$100 & "|" & 'Womens Seeding'!$B$2:$B$100, 'Womens Seeding'!$E$2:$E$100, "Not Found" )} -> 3435
A4: 2026 | B4: W03 | C4: {=_xlfn.XLOOKUP( _xlfn.SWITCH(LEFT(B4,1), "W", "Region 1", "X", "Region 2", "Y", "Region 3", "Z", "Region 4") & "|" & IF(MID(B4,2,1)="0", MID(B4,3,2), MID(B4,2,3)), 'Womens Seeding'!$D$2:$D$100 & "|" & 'Womens Seeding'!$B$2:$B$100, 'Womens Seeding'!$E$2:$E$100, "Not Found" )} -> 3276
A5: 2026 | B5: W04 | C5: {=_xlfn.XLOOKUP( _xlfn.SWITCH(LEFT(B5,1), "W", "Region 1", "X", "Region 2", "Y", "Region 3", "Z", "Region 4") & "|" & IF(MID(B5,2,1)="0", MID(B5,3,2), MID(B5,2,3)), 'Womens Seeding'!$D$2:$D$100 & "|" & 'Womens Seeding'!$B$2:$B$100, 'Womens Seeding'!$E$2:$E$100, "Not Found" )} -> 3268
A6: 2026 | B6: W05 | C6: {=_xlfn.XLOOKUP( _xlfn.SWITCH(LEFT(B6,1), "W", "Region 1", "X", "Region 2", "Y", "Region 3", "Z", "Region 4") & "|" & IF(MID(B6,2,1)="0", MID(B6,3,2), MID(B6,2,3)), 'Womens Seeding'!$D$2:$D$100 & "|" & 'Womens Seeding'!$B$2:$B$100, 'Womens Seeding'!$E$2:$E$100, "Not Found" )} -> 3279
A7: 2026 | B7: W06 | C7: {=_xlfn.XLOOKUP( _xlfn.SWITCH(LEFT(B7,1), "W", "Region 1", "X", "Region 2", "Y", "Region 3", "Z", "Region 4") & "|" & IF(MID(B7,2,1)="0", MID(B7,3,2), MID(B7,2,3)), 'Womens Seeding'!$D$2:$D$100 & "|" & 'Womens Seeding'!$B$2:$B$100, 'Womens Seeding'!$E$2:$E$100, "Not Found" )} -> 3403
A8: 2026 | B8: W07 | C8: {=_xlfn.XLOOKUP( _xlfn.SWITCH(LEFT(B8,1), "W", "Region 1", "X", "Region 2", "Y", "Region 3", "Z", "Region 4") & "|" & IF(MID(B8,2,1)="0", MID(B8,3,2), MID(B8,2,3)), 'Womens Seeding'!$D$2:$D$100 & "|" & 'Womens Seeding'!$B$2:$B$100, 'Womens Seeding'!$E$2:$E$100, "Not Found" )} -> 3228
A9: 2026 | B9: W08 | C9: {=_xlfn.XLOOKUP( _xlfn.SWITCH(LEFT(B9,1), "W", "Region 1", "X", "Region 2", "Y", "Region 3", "Z", "Region 4") & "|" & IF(MID(B9,2,1)="0", MID(B9,3,2), MID(B9,2,3)), 'Womens Seeding'!$D$2:$D$100 & "|" & 'Womens Seeding'!$B$2:$B$100, 'Womens Seeding'!$E$2:$E$100, "Not Found" )} -> 3301
A10: 2026 | B10: W09 | C10: {=_xlfn.XLOOKUP( _xlfn.SWITCH(LEFT(B10,1), "W", "Region 1", "X", "Region 2", "Y", "Region 3", "Z", "Region 4") & "|" & IF(MID(B10,2,1)="0", MID(B10,3,2), MID(B10,2,3)), 'Womens Seeding'!$D$2:$D$100 & "|" & 'Womens Seeding'!$B$2:$B$100, 'Womens Seeding'!$E$2:$E$100, "Not Found" )} -> 3235
A11: 2026 | B11: W10 | C11: {=_xlfn.XLOOKUP( _xlfn.SWITCH(LEFT(B11,1), "W", "Region 1", "X", "Region 2", "Y", "Region 3", "Z", "Region 4") & "|" & IF(MID(B11,2,1)="0", MID(B11,3,2), MID(B11,2,3)), 'Womens Seeding'!$D$2:$D$100 & "|" & 'Womens Seeding'!$B$2:$B$100, 'Womens Seeding'!$E$2:$E$100, "Not Found" )} -> 3155
A12: 2026 | B12: W11 | C12: {=_xlfn.XLOOKUP( _xlfn.SWITCH(LEFT(B12,1), "W", "Region 1", "X", "Region 2", "Y", "Region 3", "Z", "Region 4") & "|" & IF(MID(B12,2,1)="0", MID(B12,3,2), MID(B12,2,3)), 'Womens Seeding'!$D$2:$D$100 & "|" & 'Womens Seeding'!$B$2:$B$100, 'Womens Seeding'!$E$2:$E$100, "Not Found" )} -> 3193
A13: 2026 | B13: W12 | C13: {=_xlfn.XLOOKUP( _xlfn.SWITCH(LEFT(B13,1), "W", "Region 1", "X", "Region 2", "Y", "Region 3", "Z", "Region 4") & "|" & IF(MID(B13,2,1)="0", MID(B13,3,2), MID(B13,2,3)), 'Womens Seeding'!$D$2:$D$100 & "|" & 'Womens Seeding'!$B$2:$B$100, 'Womens Seeding'!$E$2:$E$100, "Not Found" )} -> 3438
... A65: 2026 | B65: Z16 | C65: {=_xlfn.XLOOKUP( _xlfn.SWITCH(LEFT(B65,1), "W", "Region 1", "X", "Region 2", "Y", "Region 3", "Z", "Region 4") & "|" & IF(MID(B65,2,1)="0", MID(B65,3,2), MID(B65,2,3)), 'Womens Seeding'!$D$2:$D$100 & "|" & 'Womens Seeding'!$B$2:$B$100, 'Womens Seeding'!$E$2:$E$100, "Not Found" )} -> 3219

Sheet WNCAATourneySlots
A1: Season | B1: Slot | C1: StrongSeed | D1: WeakSeed
A2: 2026 | B2: R1W1 | C2: W01 | D2: W16
A3: 2026 | B3: R1W2 | C3: W02 | D3: W15
A4: 2026 | B4: R1W3 | C4: W03 | D4: W14
A5: 2026 | B5: R1W4 | C5: W04 | D5: W13
A6: 2026 | B6: R1W5 | C6: W05 | D6: W12
A7: 2026 | B7: R1W6 | C7: W06 | D7: W11
A8: 2026 | B8: R1W7 | C8: W07 | D8: W10
A9: 2026 | B9: R1W8 | C9: W08 | D9: W09
A10: 2026 | B10: R1X1 | C10: X01 | D10: X16
A11: 2026 | B11: R1X2 | C11: X02 | D11: X15
A12: 2026 | B12: R1X3 | C12: X03 | D12: X14
A13: 2026 | B13: R1X4 | C13: X04 | D13: X13
... A33: 2026 | B33: R1Z8 | C33: Z08 | D33: Z09
